<mujoco model="inverted pendulum">
	<compiler inertiafromgeom="true"/>
	<default>
		<joint armature="0" limited="true"/>
		<geom contype="0" rgba="0.7 0.7 0 1"/>
		<tendon/>
	</default>
	<option gravity="0 0 -9.81" integrator="RK4" timestep="0.02"/>
	<size nstack="3000"/>
	<worldbody>
		<geom name="rail" pos="0 0 0" quat="0.707 0 0.707 0" friction="1 0.1 0.1" rgba="0.3 0.3 0.7 1" size="0.02 2" type="capsule"/>
		<body name="cart" pos="0 0 0">
			<joint axis="1 0 0" limited="true" name="slider" damping="0.5" pos="0 0 0" range="-2 2" type="slide"/>
			<geom name="cart" pos="0 0 0" mass="10" quat="0.707 0 0.707 0" size="0.1 0.1" type="capsule"/>
			<body name="pole" pos="0 0 0">
				<joint axis="0 1 0" name="hinge" damping="0.5" pos="0 0 0" limited="false" type="hinge"/>
				<geom fromto="0 0 0 0.001 0 -0.6" friction="1 0.1 0.1" name="cpole" rgba="0 0.7 0.7 1" size="0.049 0.4" type="capsule" mass="5"/>
			</body>
		</body>
	</worldbody>
	<actuator>
		<general gear="200" gainprm="1 0 0"  joint="slider" name="slide" ctrlrange="-3 3"/>
	</actuator>
</mujoco>